Workbook

Sheet VUE GLOBAL
A1: SECTEUR | B1: NB DE DOSSIERS | C1: DRE KO | D1: VT A FAIRE | E1: A REMONTER | F1: RETOUR VT | G1: DOSS A REPRENDRE | H1: DOSS A MONTER | I1: ATT INFOS CAF REF | J1: ATT DEVIS ORANGE/RIP | K1: ATT DEVIS CLIENT | L1: ATT TRAVAUX CLIENT | M1: ATT PV | N1: ATT DTA | O1: ATT COMAC/CAPFT | P1: ATT MAJ SI | Q1: POI EN TRAVAUX | R1: AT RETOUR DOE | T1: ETAT 5
A2: MEN-ROD | B2: ='MEN-ROD'!E1 -> 445 | C2: =COUNTIF('MEN-ROD'!C:C,"<="&TODAY()) -> 55 | D2: =COUNTIF('MEN-ROD'!D:D,"*01 AT VT*") -> 19 | E2: =COUNTIF('MEN-ROD'!D:D,"*01.2 A REMONTER*") -> 9 | F2: =COUNTIF('MEN-ROD'!D:D,"*02 RETOUR VT*") -> 29 | G2: =COUNTIF('MEN-ROD'!D:D,"*03 DOSSIER A REPRENDRE*") -> 5 | H2: =COUNTIF('MEN-ROD'!D:D,"*04 DOSSIER A MONTER*") -> 13 | I2: =COUNTIF('MEN-ROD'!D:D,"*05 AT INFO CAF REF*") -> 26 | J2: =COUNTIF('MEN-ROD'!D:D,"*09 AT DEVIS ORANGE/RIP*") -> 67 | K2: =COUNTIF('MEN-ROD'!D:D,"*06 AT DEVIS CLIENT*") -> 10 | L2: =COUNTIF('MEN-ROD'!D:D,"*07 AT TRVX CLIENT*") -> 86 | M2: =COUNTIF('MEN-ROD'!D:D,"*10 AT PV*") -> 15 | N2: =COUNTIF('MEN-ROD'!D:D,"*11 AT DTA*") -> 4 | O2: =COUNTIF('MEN-ROD'!D:D,"*08 AT COMAC/CAPFT*") -> 0 | P2: =COUNTIF('MEN-ROD'!D:D,"*12 AT MAJ SI*") -> 6 | Q2: =COUNTIF('MEN-ROD'!D:D,"*14 POI EN TRAVAUX*") -> 146 | R2: =COUNTIF('MEN-ROD'!D:D,"*14.1 AT RETOUR DOE*") -> 0 | T2: =COUNTIF('MEN-ROD'!D:D,"*13 ETAT 5*") -> 6
A3: GDP AQ | B3: ='GDP AQ'!E1 -> 106 | C3: =COUNTIF('GDP AQ'!C:C,"<="&TODAY()) -> 8 | D3: =COUNTIF('GDP AQ'!D:D,"*01 AT VT*") -> 11 | E3: =COUNTIF('GDP AQ'!D:D, "*01.2 A REMONTER*") -> 3 | F3: =COUNTIF('GDP AQ'!D:D,"*02 RETOUR VT*") -> 5 | G3: =COUNTIF('GDP AQ'!D:D,"*03 DOSSIER A REPRENDRE*") -> 2 | H3: =COUNTIF('GDP AQ'!D:D,"*04 DOSSIER A MONTER*") -> 5 | I3: =COUNTIF('GDP AQ'!D:D,"*5 AT INFO CAF REF*") -> 12 | J3: =COUNTIF('GDP AQ'!D:D,"*09 AT DEVIS ORANGE/RIP*") -> 2 | K3: =COUNTIF('GDP AQ'!D:D,"*06 AT DEVIS CLIENT*") -> 1 | L3: =COUNTIF('GDP AQ'!D:D,"*07 AT TRVX CLIENT*") -> 26 | M3: =COUNTIF('GDP AQ'!D:D,"*10 AT PV*") -> 9 | N3: =COUNTIF('GDP AQ'!D:D,"*11 AT DTA*") -> 2 | O3: =COUNTIF('GDP AQ'!D:D,"*08 AT COMAC/CAPFT*") -> 0 | P3: =COUNTIF('GDP AQ'!D:D,"*12 AT MAJ SI*") -> 1 | Q3: =COUNTIF('GDP AQ'!D:D,"*14 POI EN TRAVAUX*") -> 20 | R3: =COUNTIF('GDP AQ'!D:D,"*14.1 AT RETOUR DOE*") -> 5 | T3: =COUNTIF('GDP AQ'!D:D,"*13 ETAT 5*") -> 0
A4: QPR-CRO | B4: ='QPR-CRO'!E1 -> 347 | C4: =COUNTIF('QPR-CRO'!C:C,"<="&TODAY()) -> 48 | D4: =COUNTIF('QPR-CRO'!D:D,"*01 AT VT*") -> 40 | E4: =COUNTIF('QPR-CRO'!D:D,"*01.2 A REMONTER*") -> 26 | F4: =COUNTIF('QPR-CRO'!D:D,"*02 RETOUR VT*") -> 29 | G4: =COUNTIF('QPR-CRO'!D:D,"*03 DOSSIER A REPRENDRE*") -> 0 | H4: =COUNTIF('QPR-CRO'!D:D,"*04 DOSSIER A MONTER*") -> 13 | I4: =COUNTIF('QPR-CRO'!D:D,"*05 AT INFO CAF REF*") -> 24 | J4: =COUNTIF('QPR-CRO'!D:D,"*09 AT DEVIS ORANGE/RIP*") -> 14 | K4: =COUNTIF('QPR-CRO'!D:D,"*06 AT DEVIS CLIENT*") -> 6 | L4: =COUNTIF('QPR-CRO'!D:D,"*07 AT TRVX CLIENT*") -> 46 | M4: =COUNTIF('QPR-CRO'!D:D,"*10 AT PV*") -> 6 | N4: =COUNTIF('QPR-CRO'!D:D,"*11 AT DTA*") -> 0 | O4: =COUNTIF('QPR-CRO'!D:D,"*08 AT COMAC/CAPFT*") -> 0 | P4: =COUNTIF('QPR-CRO'!D:D,"*12 AT MAJ SI*") -> 10 | Q4: =COUNTIF('QPR-CRO'!D:D,"*14 POI EN TRAVAUX*") -> 56 | R4: =COUNTIF('QPR-CRO'!D:D,"*14.1 AT RETOUR DOE*") -> 65 | T4: =COUNTIF('QPR-CRO'!D:D,"*13 ETAT 5*") -> 1
A5: SECTEUR | B5: NB DE DOSSIERS | C5: DRE KO | D5: VT A FAIRE | E5: A REMONTER | F5: RETOUR VT | G5: DOSS A REPRENDRE | H5: DOSS A MONTER | I5: ATT INFOS CAF REF | J5: ATT DEVIS ORANGE/RIP | M5: ATT PV | P5: ATT MAJ SI | Q5: POI EN TRAVAUX | R5: AT RETOUR DOE | S5: RECOL A FAIRE
A6: SPI AQ | B6: ='SPI AQ'!B1 -> 73 | D6: =COUNTIF('SPI AQ'!A:A,"*01 VT A FAIRE*") -> 4 | E6: =COUNTIF('SPI AQ'!A:A, "*1.2 A REMONTER*") -> 1 | F6: =COUNTIF('SPI AQ'!A:A,"*02 RETOUR VT*") -> 2 | G6: =COUNTIF('SPI AQ'!A:A,"*03 DOSSIER A REPRENDRE*") -> 0 | H6: =COUNTIF('SPI AQ'!A:A,"*04 DOSSIER A MONTER*") -> 0 | I6: =COUNTIF('SPI AQ'!A:A,"*07 AT INFO CAF REF*") -> 15 | J6: =COUNTIF('SPI AQ'!A:A,"*08 AT DEVIS ORANGE/RIP*") -> 5 | M6: =COUNTIF('SPI AQ'!A:A,"*05 AT PV*") -> 13 | P6: =COUNTIF('SPI AQ'!A:A,"*06 AT MAJ SI*") -> 1 | Q6: =COUNTIF('SPI AQ'!A:A,"*09 POI EN TRAVAUX*") -> 15 | R6: =COUNTIF('SPI AQ'!A:A,"*09.1 ATT DOE*") -> 8 | S6: =COUNTIF('SPI AQ'!A:A,"*11 RECOL A FAIRE*") -> 0
A8: GLOBAL | B8: =B2+B3+B4+B6 -> 971 | C8: =C2+C3+C4+C6 -> 111 | D8: =D2+D3+D4+D6 -> 74 | E8: =E2+E3+E4+E6 -> 39 | F8: =F2+F3+F4+F6 -> 65 | G8: =G2+G3+G4+G6 -> 7 | H8: =H2+H3+H4+H6 -> 31 | I8: =I2+I3+I4+I6 -> 77 | ... T8: =T2+T3+T4+T6 -> 7
A10: Taux Non Confirmité | B10: =G8/F8 -> 0.10769231
A14: DOSSIER MAIN BE | B14: DOSSIER MAIN CHAFF
A15: =E2+G2 -> 14 | B15: =F2+H2 -> 42 | C15: MEN-ROD
A16: =E3+G3 -> 5 | B16: =F3+H3 -> 10 | C16: GDP AQ
A17: =E4+G4 -> 26 | B17: =F4+H4 -> 42 | C17: QPR-CRO
A18: =E6+G6 -> 1 | B18: =F6+H6 -> 2 | C18: SPI AQ
A20: =SUM(A15:A18) -> 46 | B20: =SUM(B15:B18) -> 96

Sheet MEN-ROD
C1: =TODAY() -> 46076 | E1: =COUNTA(E3:E602) -> 445 | K1: A REMPLIR PAR LE BE OBLIGATOIRE
A2: Code OEIE | B2: DRE | C2: DRE | D2: ETAT | E2: POI | F2: SJ | G2: CAFF | H2: Mémo Chaf | I2: VILLE | J2: ADRESSE | K2: DATE VT | L2: COMMENTAIRES | M2: CTC
A3: ROD401264 | B3: 46091 | C3: =VLOOKUP(E3, $A$2:$E$822, 2, FALSE) -> #N/A | D3: 14 POI EN TRAVAUX | E3: ROD401938 | F3: V1 | G3: M | H3: DMS | I3: SALLES CURAN | J3: 8 RUE DU COUVENT | K3: 45680 | L3: 13/05:les travaux seront effectués dans 2 mois (lié au ROD401689) | M3: 682776141
A4: ROD401442 | B4: 46286 | C4: =VLOOKUP(E4, $A$2:$E$822, 2, FALSE) -> #N/A | D4: 14 POI EN TRAVAUX | E4: ROD402078 | F4: AZ | G4: M | I4: ROQUEFORT SUR SOULZON | J4: L AIRE VIEILLE
A5: ROD401602 | B5: 46097 | C5: =VLOOKUP(E5, $A$2:$E$822, 2, FALSE) -> #N/A | D5: 14 POI EN TRAVAUX | E5: ROD500031 | F5: 5S | I5: SAINT JEAN DELNOUS | J5: 38 PL SAINT JEAN | K5: 45672
A6: ROD401787 | B6: 46090 | C6: =VLOOKUP(E6, $A$2:$E$822, 2, FALSE) -> #N/A | D6: 14 POI EN TRAVAUX | E6: ROD500252 | F6: RI | G6: M | I6: SAINT JEAN DELNOUS | J6: 38 PL SAINT JEAN
A7: ROD401933 | B7: 46286 | C7: =VLOOKUP(E7, $A$2:$E$822, 2, FALSE) -> #N/A | D7: 14 POI EN TRAVAUX | E7: ROD500376 | F7: 5T | G7: M | I7: PONT DE SALARS | J7: CAMBOULAS
A8: ROD401967 | B8: 46111 | C8: =VLOOKUP(E8, $A$2:$E$822, 2, FALSE) -> #N/A | D8: 14 POI EN TRAVAUX | E8: ROD500597 | F8: CN | I8: BERTHOLENE | J8: RUE PONTS | L8: LIEE A LA ROD500598
A9: ROD402054 | B9: 46076 | C9: =VLOOKUP(E9, $A$2:$E$822, 2, FALSE) -> #N/A | D9: 14 POI EN TRAVAUX | E9: ROD500605 | F9: AZ | I9: AGUESSAC | J9: 21 ROUTE ST GERMAIN | K9: 45771
A10: ROD402079 | B10: 46035 | C10: =VLOOKUP(E10, $A$2:$E$822, 2, FALSE) -> #N/A | D10: 14 POI EN TRAVAUX | E10: ROD500621 | F10: OT | I10: VILLEFRANCHE DE PANAT | J10: 1 AVENUE DU SEGALA | K10: 45785
A11: ROD500238 | B11: 46079 | C11: =VLOOKUP(E11, $A$2:$E$822, 2, FALSE) -> #N/A | D11: 14 POI EN TRAVAUX | E11: ROD500717 | F11: CR | I11: BERTHOLENE | J11: RUE PONTS BERTHOLENE
A12: ROD500263 | B12: 45994 | C12: =VLOOKUP(E12, $A$2:$E$822, 2, FALSE) -> #N/A | D12: 14 POI EN TRAVAUX | E12: ROD500644 | F12: D3 | I12: LA CAVALERIE | J12: 603 AV SIMONE VEIL | K12: 45780
A13: ROD500269 | B13: 46072 | C13: =VLOOKUP(E13, $A$2:$E$822, 2, FALSE) -> #N/A | D13: 14 POI EN TRAVAUX | E13: ROD500797 | F13: DQ | G13: M | I13: SYLVANES | J13: Chemin de Maxels
A14: ROD500302 | B14: 46252 | C14: =VLOOKUP(E14, $A$2:$E$822, 2, FALSE) -> #N/A | D14: 14 POI EN TRAVAUX | E14: ROD500780 | F14: OI | G14: M | I14: BROMMAT | J14: Rue de la Grange | K14: en cours | M14: 680459771
A15: ROD500323 | B15: 46076 | C15: =VLOOKUP(E15, $A$2:$E$822, 2, FALSE) -> #N/A | D15: 14 POI EN TRAVAUX | E15: ROD501003 | F15: VX | G15: M | I15: BROMMAT | J15: RUE DE LA GRANGE | L15: ROD500780
A16: ROD500345 | B16: 46099 | C16: =VLOOKUP(E16, $A$2:$E$822, 2, FALSE) -> #N/A | D16: 14 POI EN TRAVAUX | E16: ROD401858 | F16: AZ | I16: LIOUJAS LA LOUBIERE | J16: IMP DU COMBAL
A17: ROD500346 | B17: 46031 | C17: =VLOOKUP(E17, $A$2:$E$822, 2, FALSE) -> #N/A | D17: 14 POI EN TRAVAUX | E17: ROD501105 | F17: P0 | G17: M | I17: VABRES L ABBAYE | J17: 505 CH DES CERISIERS
A18: ROD500362 | B18: 46044 | C18: =VLOOKUP(E18, $A$2:$E$822, 2, FALSE) -> #N/A | D18: 14 POI EN TRAVAUX | E18: ROD500905 | F18: D3 | I18: NANT | J18: LA MOULINE | K18: 45832
A19: ROD500391 | B19: 46101 | C19: =VLOOKUP(E19, $A$2:$E$822, 2, FALSE) -> #N/A | D19: 14 POI EN TRAVAUX | E19: ROD500122 | F19: D3 | I19: LAGUIOLE | J19: LA SOURCE
A20: ROD500442 | B20: 46091 | C20: =VLOOKUP(E20, $A$2:$E$822, 2, FALSE) -> #N/A | D20: 14 POI EN TRAVAUX | E20: ROD501153 | F20: CN | I20: SEVERAC D AVEYRON | J20: 2 RUE DE LA CROUZETTE | K20: 45874
A21: ROD500499 | B21: 46086 | C21: =VLOOKUP(E21, $A$2:$E$822, 2, FALSE) -> #N/A | D21: 14 POI EN TRAVAUX | E21: ROD501245 | F21: AZ | I21: MONTLAUR | J21: 166 CH DU MAS DE DAURELLE | K21: 45901 | L21: Demande DTA le 6/10
A22: ROD500519 | B22: 46020 | C22: =VLOOKUP(E22, $A$2:$E$822, 2, FALSE) -> #N/A | D22: 14 POI EN TRAVAUX | E22: ROD500756 | F22: 5I | I22: SAINT JEAN DU BRUEL | J22: RTE DE SEINGLEYS
A23: ROD500565 | B23: 46076 | C23: =VLOOKUP(E23, $A$2:$E$822, 2, FALSE) -> #N/A | D23: 14 POI EN TRAVAUX | E23: ROD501111 | F23: V1 | G23: C | I23: LE FEL | J23: 380 CH DU PUECH DE CASSOS
A24: ROD500627 | B24: 46086 | C24: =VLOOKUP(E24, $A$2:$E$822, 2, FALSE) -> #N/A | D24: 14 POI EN TRAVAUX | E24: ROD501229 | F24: D3 | G24: C | I24: SAINT JEAN DU BRUEL | J24: RTE NANT | K24: 45890
A25: ROD500638 | B25: 46078 | C25: =VLOOKUP(E25, $A$2:$E$822, 2, FALSE) -> #N/A | D25: 14 POI EN TRAVAUX | E25: ROD501747 | F25: GC | G25: M | I25: BROMMAT | J25: RUE DE LA GRANGE | L25: liée à la ROD501003
A26: ROD500708 | B26: 46086 | C26: =VLOOKUP(E26, $A$2:$E$822, 2, FALSE) -> #N/A | D26: 14 POI EN TRAVAUX | E26: ROD500610 | F26: 5S | I26: MILLAU | J26: 16B BD AYROLLE
A27: ROD500710 | B27: 46231 | C27: =VLOOKUP(E27, $A$2:$E$822, 2, FALSE) -> #N/A | D27: 14 POI EN TRAVAUX | E27: ROD500387 | F27: D3 | I27: SAINT AFFRIQUE | J27: 2 RUE JEAN BOUDOU
A28: ROD500727 | B28: 46272 | C28: =VLOOKUP(E28, $A$2:$E$822, 2, FALSE) -> #N/A | D28: 14 POI EN TRAVAUX | E28: ROD501175 | F28: D3 | G28: C | I28: VILLEFRANCHE DE PANAT | J28: 6 AV DE LA PLAGE | K28: 45876
A29: ROD500728 | B29: 46084 | C29: =VLOOKUP(E29, $A$2:$E$822, 2, FALSE) -> #N/A | D29: 14 POI EN TRAVAUX | E29: ROD500730 | F29: 5J | G29: M | I29: CAMBOULAS | J29: PONT DE SALARS
A30: ROD500755 | B30: 46087 | C30: =VLOOKUP(E30, $A$2:$E$822, 2, FALSE) -> #N/A | D30: 14 POI EN TRAVAUX | E30: ROD500423 | F30: D3 | G30: M | I30: CASSAGNES BEGONHES | J30: LE BOUYSSONIS
A31: ROD500771 | B31: 46213 | C31: =VLOOKUP(E31, $A$2:$E$822, 2, FALSE) -> #N/A | D31: 14 POI EN TRAVAUX | E31: ROD500273 | F31: OI | G31: M | I31: COUBISOU | J31: ROUTE DE LACAZE | K31: 45770
A32: ROD500783 | B32: 46091 | C32: =VLOOKUP(E32, $A$2:$E$822, 2, FALSE) -> #N/A | D32: 14 POI EN TRAVAUX | E32: ROD500496 | F32: OI | G32: M | I32: COUBISOU | J32: ROUTE DE LACAZE
A33: ROD500816 | B33: 46248 | C33: =VLOOKUP(E33, $A$2:$E$822, 2, FALSE) -> #N/A | D33: 14 POI EN TRAVAUX | E33: ROD501002 | F33: VX | G33: M | I33: COUBISOU | J33: ROUTE DE LACAZE | L33: ROD500273
A34: ROD500862 | B34: 46239 | C34: =VLOOKUP(E34, $A$2:$E$822, 2, FALSE) -> #N/A | D34: 14 POI EN TRAVAUX | E34: ROD500369 | F34: OI | G34: M | I34: MILLAU | J34: CHEMIN DES HAUTS DE PRIGNOLLES | K34: 20/03/2025 en cours | L34: 13/05: un mail a été envoyé | M34: 565608331
A35: ROD500885 | B35: 46079 | C35: =VLOOKUP(E35, $A$2:$E$822, 2, FALSE) -> #N/A | D35: 14 POI EN TRAVAUX | E35: ROD501131 | F35: 5S | G35: C | I35: BOZOULS | J35: AVENUE COMBE CROZES | L35: mail envoyé au client
A36: ROD500893 | B36: 46076 | C36: =VLOOKUP(E36, $A$2:$E$822, 2, FALSE) -> #N/A | D36: 14 POI EN TRAVAUX | E36: ROD501566 | F36: OT | G36: C | I36: CORNUS | J36: 76 RUE DE LA TRIVALLE | K36: 45951
A37: ROD500992 | B37: 46101 | C37: =VLOOKUP(E37, $A$2:$E$822, 2, FALSE) -> #N/A | D37: 14 POI EN TRAVAUX | E37: ROD500264 | F37: OI | G37: C | I37: CAMBOULAZET | J37: RTE DE LA RIVIERE | K37: 45715 | L37: FIN TVX: FIN JUIN 2025 | M37: 565451655
A38: ROD500998 | B38: 46106 | C38: =VLOOKUP(E38, $A$2:$E$822, 2, FALSE) -> #N/A | D38: 14 POI EN TRAVAUX | E38: ROD500144 | F38: OI | G38: M | I38: SAINT GENIEZ D OLT ET D AUBRAC | J38: 5802 PL GEN DE GAULLE | K38: 45692
A39: ROD501081 | B39: 46092 | C39: =VLOOKUP(E39, $A$2:$E$822, 2, FALSE) -> #N/A | D39: 14 POI EN TRAVAUX | E39: ROD501365 | F39: 5T | G39: C | H39: Att travaux ACF011 | I39: ESPEYRAC | J39: RTE NOLORGUES | K39: 45918
A40: ROD501101 | B40: 46092 | C40: =VLOOKUP(E40, $A$2:$E$822, 2, FALSE) -> #N/A | D40: 14 POI EN TRAVAUX | E40: ROD500574 | F40: 5J | G40: C | I40: LUC LA PRIMAUBE | J40: RTE DE LA BOISSONNADE | K40: 30/04/2025 9H
...

Sheet QPR-CRO
A1: =TODAY() -> 46076 | E1: =COUNTA(E3:E672) -> 347 | J1: A REMPLIR PAR LE BE OBLIGATOIRE
A2: Code OEIE | B2: DRE | C2: DRE | D2: ETAT | E2: POI | F2: SJ | G2: Mémo Chaf | H2: VILLE | I2: ADRESSE | J2: DATE VT | K2: Chargé | L2: COMMENTAIRES
A3: QPR600247 | B3: 46083 | C3: =VLOOKUP(E3, $A$3:$E$704, 2, FALSE) -> #N/A | D3: 15 POI FACTU | E3: VAN004278 | F3: QQ | H3: Quiberon | I3: 7 QU OCEAN | J3: 45947 | L3: Same as VAN004277
C4: =VLOOKUP(E4, $A$3:$E$704, 2, FALSE) -> #N/A | D4: 15 POI FACTU | E4: VAN500832 | F4: B3 | G4: S04 CRASH | H4: NIVILLAC | I4: RUE JOSEPH SAUVEUR | J4: 46030 | K4: amrou
A5: QPR500885 | B5: 46192 | C5: =VLOOKUP(E5, $A$3:$E$704, 2, FALSE) -> #N/A | D5: 14.1 AT RETOUR DOE | E5: QPR500660 | F5: F9 | H5: Quimper | I5: 12 R BECQUEREL | J5: VT faite le 09/07
A6: LOR500732 | B6: 46080 | C6: =VLOOKUP(E6, $A$3:$E$704, 2, FALSE) -> #N/A | D6: 14.1 AT RETOUR DOE | E6: QPR500654 | F6: 5Y | G6: Att GEOREF | H6: Plogastel-Saint-Germain | I6: 12 STAN KELERON | J6: 45826
A7: RRE501172 | B7: 46072 | C7: =VLOOKUP(E7, $A$3:$E$704, 2, FALSE) -> #N/A | D7: 14.1 AT RETOUR DOE | E7: QPR501059 | F7: F9 | G7: proposition d'attachement | H7: Plouhinec, Finistère | I7: R DE LA CROIX DONNART | J7: VT faite le 09/07
A8: RRE501199 | B8: 46115 | C8: =VLOOKUP(E8, $A$3:$E$704, 2, FALSE) -> #N/A | D8: 14.1 AT RETOUR DOE | E8: QPR500784 | F8: JG | G8: Manque DOE + cloture LINE | H8: Loctudy | I8: 25 RUE DU PORT | J8: à remonter par ghada
A9: VAN501393 | B9: 46097 | C9: =VLOOKUP(E9, $A$3:$E$704, 2, FALSE) -> #N/A | D9: 14.1 AT RETOUR DOE | E9: QPR500679 | F9: 5Y | G9: Manque RT GCD020 GEO cloturé | H9: Plobannalec-Lesconil | I9: 2B RUE DE KARREK KREIZ | J9: 45825
A10: QPR500983 | B10: 46086 | C10: =VLOOKUP(E10, $A$3:$E$704, 2, FALSE) -> #N/A | D10: 14.1 AT RETOUR DOE | E10: QPR401859
A11: LOR500806 | B11: 46296 | C11: =VLOOKUP(E11, $A$3:$E$704, 2, FALSE) -> #N/A | D11: 14.1 AT RETOUR DOE | E11: QPR402292
A12: QPR501023 | B12: 46063 | C12: =VLOOKUP(E12, $A$3:$E$704, 2, FALSE) -> #N/A | D12: 14.1 AT RETOUR DOE | E12: QPR501038 | F12: 5S | H12: Quéménéven | I12: TY FORN | L12: urgent mail envoyé concernant
A13: LOR500883 | B13: 46149 | C13: =VLOOKUP(E13, $A$3:$E$704, 2, FALSE) -> #N/A | D13: 14.1 AT RETOUR DOE | E13: LOR400490 | F13: 5Y | G13: Factu a faire | H13: PLUMELIAU BIEUZY | I13: 10 IMP DES NENUPHARS
A14: VAN501638 | B14: 46084 | C14: =VLOOKUP(E14, $A$3:$E$704, 2, FALSE) -> #N/A | D14: 14.1 AT RETOUR DOE | E14: VAN401205 | G14: PAS Accès LINE CRASH
A15: LOR500901 | B15: 46063 | C15: =VLOOKUP(E15, $A$3:$E$704, 2, FALSE) -> #N/A | D15: 14.1 AT RETOUR DOE | E15: QPR300617 | G15: Cloture LINE
A16: LOR500925 | B16: 46119 | C16: =VLOOKUP(E16, $A$3:$E$704, 2, FALSE) -> #N/A | D16: 14.1 AT RETOUR DOE | E16: RRE400009 | G16: Attente DOE + Attachement
A17: RRE501484 | B17: 45985 | C17: =VLOOKUP(E17, $A$3:$E$704, 2, FALSE) -> #N/A | D17: 14.1 AT RETOUR DOE | E17: VAN202306 | G17: Attente DOE + Attachement CRASH
A18: RRE501518 | B18: 46045 | C18: =VLOOKUP(E18, $A$3:$E$704, 2, FALSE) -> #N/A | D18: 14.1 AT RETOUR DOE | E18: QPR402301 | G18: RECOL LINE TIGRE OK
A19: RRE501554 | B19: 46073 | C19: =VLOOKUP(E19, $A$3:$E$704, 2, FALSE) -> #N/A | D19: 14.1 AT RETOUR DOE | E19: VAN402909 | G19: RECOL LINE TIGRE OK
A20: VAN501849 | B20: 46084 | C20: =VLOOKUP(E20, $A$3:$E$704, 2, FALSE) -> #N/A | D20: 14.1 AT RETOUR DOE | E20: RRE402429 | G20: Attente DOE + Attachement
A21: LOR501020 | B21: 46087 | C21: =VLOOKUP(E21, $A$3:$E$704, 2, FALSE) -> #N/A | D21: 14.1 AT RETOUR DOE | E21: RRE401267 | G21: Att modif Attachement
A22: QPR501326 | B22: 46084 | C22: =VLOOKUP(E22, $A$3:$E$704, 2, FALSE) -> #N/A | D22: 14.1 AT RETOUR DOE | E22: LOR401481 | G22: Clôture LINE
A23: LOR501040 | B23: 46756 | C23: =VLOOKUP(E23, $A$3:$E$704, 2, FALSE) -> #N/A | D23: 14.1 AT RETOUR DOE | E23: RRE402093 | G23: Clôture LINE
A24: LOR501041 | B24: 46083 | C24: =VLOOKUP(E24, $A$3:$E$704, 2, FALSE) -> #N/A | D24: 14.1 AT RETOUR DOE | E24: LOR401381 | G24: Clôture LINE CRASH
A25: QPR501355 | B25: 46097 | C25: =VLOOKUP(E25, $A$3:$E$704, 2, FALSE) -> #N/A | D25: 14.1 AT RETOUR DOE | E25: LOR401177 | G25: Clôture LINE
... A55: QPR501901 | B55: 46050 | C55: =VLOOKUP(E55, $A$3:$E$704, 2, FALSE) -> #N/A | D55: 14.1 AT RETOUR DOE | E55: QPR400498 | G55: GEOREF EN ATT
A56: QPR501902 | B56: 46073 | C56: =VLOOKUP(E56, $A$3:$E$704, 2, FALSE) -> #N/A | D56: 14.1 AT RETOUR DOE | E56: QPR300168
A57: QPR501908 | B57: 46085 | C57: =VLOOKUP(E57, $A$3:$E$704, 2, FALSE) -> #N/A | D57: 14.1 AT RETOUR DOE | E57: QPR400186
A58: VAN502650 | B58: 46084 | C58: =VLOOKUP(E58, $A$3:$E$704, 2, FALSE) -> #N/A | D58: 14.1 AT RETOUR DOE | E58: QPR400286
A59: CRO500257 | B59: 46050 | C59: =VLOOKUP(E59, $A$3:$E$704, 2, FALSE) -> #N/A | D59: 14.1 AT RETOUR DOE | E59: BRS302246
A60: LOR501421 | B60: 46087 | C60: =VLOOKUP(E60, $A$3:$E$704, 2, FALSE) -> #N/A | D60: 14.1 AT RETOUR DOE | E60: QPR103602
A61: QPR501916 | B61: 46090 | C61: =VLOOKUP(E61, $A$3:$E$704, 2, FALSE) -> #N/A | D61: 14.1 AT RETOUR DOE | E61: QPR300274 | G61: REO ETUDE
A62: QPR501919 | B62: 46069 | C62: =VLOOKUP(E62, $A$3:$E$704, 2, FALSE) -> #N/A | D62: 14.1 AT RETOUR DOE | E62: QPR300167
A63: CRO500258 | B63: 46090 | C63: =VLOOKUP(E63, $A$3:$E$704, 2, FALSE) -> #N/A | D63: 14.1 AT RETOUR DOE | E63: VAN202637
A64: LOR501433 | B64: 46097 | C64: =VLOOKUP(E64, $A$3:$E$704, 2, FALSE) -> #N/A | D64: 14.1 AT RETOUR DOE | E64: RRE402217
A65: VAN502671 | B65: 46084 | C65: =VLOOKUP(E65, $A$3:$E$704, 2, FALSE) -> #N/A | D65: 14.1 AT RETOUR DOE | E65: RRE500820 | F65: KA | H65: Val-d'Izé | I65: LD LES NACHARDAIS | J65: Photos sur sharepoint
A66: CRO500259 | B66: 46091 | C66: =VLOOKUP(E66, $A$3:$E$704, 2, FALSE) -> #N/A | D66: 14.1 AT RETOUR DOE | E66: RRE400998 | F66: JG | G66: DOE + proposition att | H66: PIRE CHANCE | I66: R DE BOISTRUDAN | J66: ? | L66: tous les documents envoyées à cynthia ou stephane
A67: QPR501964 | B67: 46078 | C67: =VLOOKUP(E67, $A$3:$E$704, 2, FALSE) -> #N/A | D67: 14.1 AT RETOUR DOE | E67: VAN501004 | F67: KA | G67: Manque cloture ACF010 | H67: Le Cours | I67: KERBRANQUET | J67: à remonter par khadher
A68: QPR501965 | B68: 46076 | C68: =VLOOKUP(E68, $A$3:$E$704, 2, FALSE) -> #N/A | D68: 14.1 AT RETOUR DOE | E68: QPR500419 | F68: KA | G68: Manque cloture ACF010 + ACF011 + manque DMS + proposition attachement | H68: Pluguffan | I68: ROUTE DE LEUBIN | J68: 45854
A69: LOR501475 | B69: 46076 | C69: =VLOOKUP(E69, $A$3:$E$704, 2, FALSE) -> #N/A | D69: 14.1 AT RETOUR DOE | E69: QPR401299 | F69: 5Z | G69: Recollement a faire pas acces a LINE reesaye | H69: Audierne | I69: BOULEVARD JEAN MOULIN | J69: 45924
...

Sheet GDP AQ
A1: =TODAY() -> 46076 | E1: =COUNTA(E3:E745) -> 106 | J1: A REMPLIR PAR LE BE OBLIGATOIRE
A2: Code OEIE | B2: DRE | C2: DRE | D2: ETAT | E2: POI | F2: SJ | G2: Mémo Chaf | H2: VILLE | I2: ADRESSE | J2: DATE VT | K2: COMMENTAIRES
A3: MDM102429 | B3: 46111 | C3: =VLOOKUP(E3, $A$2:$E$822, 2, FALSE) -> #N/A | D3: 14.1 AT RETOUR DOE | E3: PAU400540 | F3: XR | G3: Manque classe A pour recol | H3: BUROS | I3: 2265 CHE ROUMIEU
A4: MDM103892 | B4: 46085 | C4: =VLOOKUP(E4, $A$2:$E$822, 2, FALSE) -> #N/A | D4: 14.1 AT RETOUR DOE | E4: PAU101592 | F4: CC | H4: HAGETAUBIN | I4: 1350 RTE ST MEDARD | K4: TVX FINIS
A5: MDM200033 | B5: 46084 | C5: =VLOOKUP(E5, $A$2:$E$822, 2, FALSE) -> #N/A | D5: 14.1 AT RETOUR DOE | E5: MDM300296 | F5: CC | H5: MONT DE MARSAN | I5: R PIERRE RISPAL
A6: MDM201114 | B6: 46083 | C6: =VLOOKUP(E6, $A$2:$E$822, 2, FALSE) -> #N/A | D6: 14.1 AT RETOUR DOE | E6: BAY400463 | F6: CC | H6: SAINT MARTIN DE HINX | I6: RTE VIGNERONS
A7: MDM300394 | B7: 46104 | C7: =VLOOKUP(E7, $A$2:$E$822, 2, FALSE) -> #N/A | D7: 14.1 AT RETOUR DOE | E7: MDM500515 | F7: CP | H7: GAMARDE LES BAINS | I7: ROUTE DE TENDURE | K7: a reprendre? pourquoi ????
A8: BAY300372 | B8: 46090 | C8: =VLOOKUP(E8, $A$2:$E$822, 2, FALSE) -> #N/A | D8: 14 POI EN TRAVAUX | E8: PAU400255 | F8: CC | H8: SAINT CASTIN | I8: RTE BUROS | J8: 45729
A9: BAY300536 | B9: 46084 | C9: =VLOOKUP(E9, $A$2:$E$822, 2, FALSE) -> #N/A | D9: 14 POI EN TRAVAUX | E9: PAU400058 | F9: RV | H9: GERDEREST | I9: CH DE MONASSUT | J9: ? | K9: pas de travaux client fibré déja
A10: MDM300689 | B10: 46119 | C10: =VLOOKUP(E10, $A$2:$E$822, 2, FALSE) -> #N/A | D10: 14 POI EN TRAVAUX | E10: PAU301083 | F10: DI | G10: DOSSIER A VALIDER | H10: JURANCON | I10: 1 RUE DE LA SCIERIE | J10: 45931 | K10: Pris en charge par stéphane
A11: MDM301155 | B11: 46090 | C11: =VLOOKUP(E11, $A$2:$E$822, 2, FALSE) -> #N/A | D11: 14 POI EN TRAVAUX | E11: PAU103623 | F11: CC | H11: MORLANNE | I11: ROUTE PERE
A12: PAU301084 | B12: 46162 | C12: =VLOOKUP(E12, $A$2:$E$822, 2, FALSE) -> #N/A | D12: 14 POI EN TRAVAUX | E12: MDM500332 | F12: CC | H12: BAHUS SOUBIRAN | I12: RTE DE DAMOULENS | J12: 45835 | K12: TRVX ENEDIS FAITES
A13: MDM301222 | B13: 46078 | C13: =VLOOKUP(E13, $A$2:$E$822, 2, FALSE) -> #N/A | D13: 14 POI EN TRAVAUX | E13: MDM500161 | F13: CC | H13: PONTENX LES FORGES | I13: 607 RTE MOUGNAN | K13: TVX OK
A14: PAU301245 | B14: 46080 | C14: =VLOOKUP(E14, $A$2:$E$822, 2, FALSE) -> #N/A | D14: 14 POI EN TRAVAUX | E14: MDM400853 | F14: XR | H14: BEGAAR | I14: 218 CHEMIN POUCHIOU
A15: MDM301401 | B15: 46188 | C15: =VLOOKUP(E15, $A$2:$E$822, 2, FALSE) -> #N/A | D15: 14 POI EN TRAVAUX | E15: MDM200689 | F15: DO | H15: AUREILHAN | I15: 21 RTE LACS
A16: MDM400167 | B16: 46079 | C16: =VLOOKUP(E16, $A$2:$E$822, 2, FALSE) -> #N/A | D16: 14 POI EN TRAVAUX | E16: MDM003509 | F16: DG | H16: GEAUNE | I16: R NAZ DE GUIT | J16: 45723
A17: PAU400195 | B17: 46090 | C17: =VLOOKUP(E17, $A$2:$E$822, 2, FALSE) -> #N/A | D17: 14 POI EN TRAVAUX | E17: DAX400043 | F17: DO | H17: PONTONX SUR L'ADOUR | I17: 81 CHE CASTERA
A18: MDM400322 | B18: 46097 | C18: =VLOOKUP(E18, $A$2:$E$822, 2, FALSE) -> #N/A | D18: 14 POI EN TRAVAUX | E18: DAX400041 | F18: DO | H18: PONTONX SUR L'ADOUR | I18: CH NOEL | J18: 45724
A19: PAU400369 | B19: 46083 | C19: =VLOOKUP(E19, $A$2:$E$822, 2, FALSE) -> #N/A | D19: 14 POI EN TRAVAUX | E19: BAY400353 | F19: CC | H19: TARNOS | I19: 781 CHE ANNELONGUE | J19: 45932
A20: MDM400398 | B20: 46086 | C20: =VLOOKUP(E20, $A$2:$E$822, 2, FALSE) -> #N/A | D20: 14 POI EN TRAVAUX | E20: BAY200287 | F20: DO | H20: LABENNE | I20: 1 ALL CHAMPAGNE
A21: MDM400427 | B21: 46128 | C21: =VLOOKUP(E21, $A$2:$E$822, 2, FALSE) -> #N/A | D21: 14 POI EN TRAVAUX | E21: ARC500883 | F21: CG | H21: GUJAN MESTRAS | I21: 8 ALL DU BOSQUET DES CIGALES | K21: amenagement
A22: BAY400496 | B22: 46084 | C22: =VLOOKUP(E22, $A$2:$E$822, 2, FALSE) -> #N/A | D22: 14 POI EN TRAVAUX | E22: MDM300753 | F22: BX | H22: SARBAZAN | I22: 683 POUY | K22: TVX OK (photos travaux sur share point)
A23: BAY400497 | B23: 46084 | C23: =VLOOKUP(E23, $A$2:$E$822, 2, FALSE) -> #N/A | D23: 14 POI EN TRAVAUX | E23: PAU300808 | F23: OI | H23: GELOS | I23: AVE HENRI FANFELLE | J23: 45950 | K23: j'ai vous transferé le mail du client ou il nous a confirmé que les travaux ont été terminés
A24: BAY400498 | B24: 46084 | C24: =VLOOKUP(E24, $A$2:$E$822, 2, FALSE) -> #N/A | D24: 14 POI EN TRAVAUX | E24: MDM500507 | F24: BW | H24: MUGRON | I24: 248 RTE DE POMAREZ | J24: 45937
A25: MDM400530 | B25: 46148 | C25: =VLOOKUP(E25, $A$2:$E$822, 2, FALSE) -> #N/A | D25: 14 POI EN TRAVAUX | E25: ARC500798 | F25: OG | H25: ARCACHON | I25: 38 AV DES GOELANDS
A26: MDM400881 | B26: 46090 | C26: =VLOOKUP(E26, $A$2:$E$822, 2, FALSE) -> #N/A | D26: 14 POI EN TRAVAUX | E26: MDM300446 | F26: CC | H26: CASTELNER | I26: LASSERRE | J26: 45950 | K26: Pas de dépose d'appui de notre part. | Appui ENEDIS déjà déposés
A27: MDM400978 | B27: 46099 | C27: =VLOOKUP(E27, $A$2:$E$822, 2, FALSE) -> #N/A | D27: 14 POI EN TRAVAUX | E27: PAU301246 | F27: DI | H27: MIREPEIX | I27: RUE BAREILLE | J27: 45937 | K27: lié a PAU301245
A28: MDM500002 | B28: 46078 | C28: =VLOOKUP(E28, $A$2:$E$822, 2, FALSE) -> 46076 | D28: 12 AT MAJ SI | E28: ARC600065 | F28: IN | H28: LE TEICH | I28: 48 RUE DES POISSONNIERS | J28: 46050
A29: MDM500310 | B29: 46083 | C29: =VLOOKUP(E29, $A$2:$E$822, 2, FALSE) -> 46077 | D29: 11 AT DTA | E29: ARC500878 | F29: IK | G29: Rapport d'ammiante existant ou non | H29: LE TEICH | I29: 1 ALL DE CANTELAUDE | K29: Besoin retour terrain
A30: MDM500366 | B30: 46146 | C30: =VLOOKUP(E30, $A$2:$E$822, 2, FALSE) -> 46077 | D30: 11 AT DTA | E30: ARC500965 | F30: IK | G30: Rapport d'ammiante existant ou non | H30: LE TEICH | I30: 1 ALL DE CANTELAUDE | J30: 46037
A31: MDM500477 | B31: 46078 | C31: =VLOOKUP(E31, $A$2:$E$822, 2, FALSE) -> 46078 | D31: 10 AT PV | E31: ARC500827 | F31: OG | H31: LA TESTE DE BUCH | I31: 7 SQ LUDWIG VAN BEETHOVEN
A32: MDM500499 | B32: 46078 | C32: =VLOOKUP(E32, $A$2:$E$822, 2, FALSE) -> 46078 | D32: 10 AT PV | E32: MDM301222 | F32: CC | G32: Recus | H32: SAINT PERDON | I32: RTE CALOY | J32: 45726
A33: MDM500500 | B33: 46078 | C33: =VLOOKUP(E33, $A$2:$E$822, 2, FALSE) -> 46078 | D33: 10 AT PV | E33: ARC500960 | F33: IN | G33: Pres PV | H33: SALLES | I33: CHEMIN DE GUERIN | J33: 46022
A34: MDM500532 | B34: 46078 | C34: =VLOOKUP(E34, $A$2:$E$822, 2, FALSE) -> 46080 | D34: 10 AT PV | E34: ARC500930 | F34: IN | H34: LA TESTE DE BUCH | I34: CHE DE PECHIC | J34: 46022
A35: MDM500538 | B35: 46086 | C35: =VLOOKUP(E35, $A$2:$E$822, 2, FALSE) -> 46078 | D35: 10 AT PV | E35: ARC600021 | F35: 59 | H35: GUJAN MESTRAS | I35: 12 B AV DE CESAREE | J35: On a passé déja ?
A36: ARC500708 | B36: 46127 | C36: =VLOOKUP(E36, $A$2:$E$822, 2, FALSE) -> 46083 | D36: 10 AT PV | E36: ARC600070 | F36: OG | G36: ETUDE FAISABILITE OK demande PV sur la ARC500902 | H36: LUGOS | I36: RUE DE L EGLISE
A37: ARC500728 | B37: 46072 | C37: =VLOOKUP(E37, $A$2:$E$822, 2, FALSE) -> 46076 | D37: 10 AT PV | E37: ARC600069 | F37: OG | G37: dossier liée a la ARC500728PV lancer | H37: SALLES | I37: ROUTE DE LA GARENNE
A38: ARC500733 | B38: 46083 | C38: =VLOOKUP(E38, $A$2:$E$822, 2, FALSE) -> 46078 | D38: 10 AT PV | E38: ARC600039 | F38: 9I | G38: tvx debut avril | H38: LE TEICH | I38: 1 E ALL DE CANTELAUDE | J38: 20/01 à 14h
A39: ARC500784 | B39: 46087 | C39: =VLOOKUP(E39, $A$2:$E$822, 2, FALSE) -> 46083 | D39: 10 AT PV | E39: ARC600003 | F39: 9I | H39: GUJAN MESTRAS | I39: 5 R DU CHATEAU | J39: 22/01 à 9h30
A40: ARC500802 | B40: 46084 | C40: =VLOOKUP(E40, $A$2:$E$822, 2, FALSE) -> 46073 | D40: 09 AT DEVIS ORANGE/RIP | E40: ARC500847 | F40: IN | G40: Etude de faisabilité | H40: LUGOS | I40: RUE DE L EGLISE
...

Sheet PRESENTATION 
B1: SUIVI DOSSIER ETUDE

Sheet SPI AQ
A1: =TODAY() -> 46076 | B1: =COUNTA(B3:B774) -> 73 | I1: PV | M1: DTA
A2: ETAT | B2: RechercheSPI | C2: VILLE | D2: Adresse | E2: Date création | F2: Date VT | G2: Date VT <14j | H2: N° SAVOIR | I2: Date émision PV | J2: Relance | L2: Dat PV recu | M2: N°BANBOU | N2: Date émission DTA | O2: DATE RELANCE | P2: INFO CAF
A3: 09.1 ATT DOE | B3: IMI-VA-64122/00RM-1 | C3: BIARRITZ | D3: 31 PASSAGE MAZAGRAN | E3: 45755 | G3: =E3+14 -> 45769
A4: 09.1 ATT DOE | B4: IMI-VA-64122/02WK-1 | C4: BIARRITZ | D4: 36 AVENUE DE L IMPERATRICE | E4: 45658 | G4: =E4+14 -> 45672 | P4: PB AVEC TRAVAUX
A5: 09.1 ATT DOE | B5: IMI-VA-40114/017S-1 | C5: GOURBERA | D5: 2450 RTE DE HERM | E5: 45661 | G5: =E5+14 -> 45675 | P5: PB AVEC TRAVAUX
A6: 09.1 ATT DOE | B6: IMI-VA-40279/169O-1 | C6: ST PAUL les DAX | D6: 332 CHEMIN DES ARTIFICIERS | E6: 45780 | G6: =E6+14 -> 45794 | H6: 1080316 | I6: 45832 | L6: 45910
A7: 09.1 ATT DOE | B7: IMI-VA-64024/02WH-1 | C7: ANGLET | D7: 14 avenue du vallon | E7: 45690 | G7: =E7+14 -> 45704 | I7: 45824 | L7: 45905 | P7: A faire
A8: 09.1 ATT DOE | B8: IMI-VA-40234/0083-1 | C8: POUYDESSSEAUX | D8: ROUTE DE CORBLEU | E8: 45887 | G8: =E8+14 -> 45901 | I8: 45912 | L8: 45926
A9: 09.1 ATT DOE | B9: IMI-VA-40234/009R-1 | C9: POUYDESSSEAUX | D9: 1549 route de bostens | E9: 45926 | F9: 45936 | G9: =E9+14 -> 45940 | H9: 1088187 | I9: 45915 | L9: 45944 | P9: Att fiche GESPOT
A10: 09.1 ATT DOE | B10: IMI-VA-40179/00LQ-3 | C10: MEES | D10: ROUTE D ARDY | E10: 45658 | G10: =E10+14 -> 45672
A11: 09 POI EN TRAVAUX | B11: IMI-VA-64024/04RO-2 | C11: ANGLET | D11: 3 RUE DE GRAVILLE | E11: 45658 | G11: =E11+14 -> 45672
A12: 09 POI EN TRAVAUX | B12: IMI-VA-64125/02AH-1 | C12: BIDART | D12: chemin cartacan | E12: 45658 | G12: =E12+14 -> 45672
A13: 09 POI EN TRAVAUX | B13: IMI-VA-40139/006Y-1 | C13: LAGLORIEUSE | D13: 2711 ROUTE DE PUJO | E13: 45866 | G13: =E13+14 -> 45880 | I13: 45910 | L13: 45926
A14: 09 POI EN TRAVAUX | B14: IMI-VA-64024/06OS-1 | C14: ANGLET | D14: 108 PROMENADE DE LA BARRE | E14: 45918 | F14: 45932 | G14: =E14+14 -> 45932 | H14: 1093487 | I14: 45911 | L14: 45943
A15: 09 POI EN TRAVAUX | B15: IMI-VA-64102/01VV-1 | C15: BAYONNE | D15: 4 AVENUE MARTHE JEAN | E15: 45943 | F15: 45947 | G15: =E15+14 -> 45957 | I15: 45952 | L15: 45967
A16: 09 POI EN TRAVAUX | B16: IMI-VA-64024/02Y4-1 | C16: ANGLET | D16: 96 BOULEVARD DES PLAGES | E16: 45981 | G16: =E16+14 -> 45995 | H16: 1096785 | I16: 45992 | L16: 45995
A17: 09 POI EN TRAVAUX | B17: IMI-VA-40202/01WO-1 | C17: NARROSSE | D17: 944 ROUTE DE SORT | E17: 45960 | G17: =E17+14 -> 45974 | H17: 1095230 | I17: 45978 | L17: 45994
A18: 09 POI EN TRAVAUX | B18: IMI-VA-40123/01L0-1 | C18: HERM | D18: 1110 ROUTE DE CLUQUELARDIT | E18: 45876 | G18: =E18+14 -> 45890 | I18: 45901 | L18: NA
A19: 09 POI EN TRAVAUX | B19: IMI-VA-40125/00GJ-1 | C19: HEUGAS | D19: 2211 ROUTE DU BRAOU | E19: 45936 | F19: 45937 | G19: =E19+14 -> 45950 | I19: 45950 | L19: 45979
A20: 09 POI EN TRAVAUX | B20: IMI-VA-40314/01QH-1 | C20: TERCIS LES BAINS | D20: 122 CHEMIN DU TASTET | E20: 45866 | G20: =E20+14 -> 45880 | I20: 45874 | L20: 45911
A21: 09 POI EN TRAVAUX | B21: IMI-VA-40003/013O-1 | C21: ANGOUME | D21: ROUTE DE MEES | E21: 45999 | F21: 46003 | G21: =E21+14 -> 46013
A22: 09 POI EN TRAVAUX | B22: IMI-VA-40279/15MF-1 | C22: ST PAUL les DAX | D22: 5396 AVENUE DES LACS | E22: 45742 | G22: =E22+14 -> 45756 | H22: 1072498 | I22: 45755 | L22: 46006 | P22: PB AVEC TRAVAUX
A23: 09 POI EN TRAVAUX | B23: IMI-VA-64102/044Q-1 | C23: BAYONNE | D23: 38 RUE MAUBEC | E23: 45988 | G23: =E23+14 -> 46002 | H23: 1097537 | I23: 45999 | L23: 46017
A24: 09 POI EN TRAVAUX | B24: IMI-VA-40280/00C8-2 | C24: ST PERDON | D24: 1700 ROUTE DE TOINE | F24: 46051 | G24: =E24+14 -> 14
A25: 09 POI EN TRAVAUX | B25: IMI-VA-40192/053X-2 | C25: MONT DE MARSAN | D25: 93 AVENUE DU MARECHAL FOCH | E25: 45905 | G25: =E25+14 -> 45919 | H25: 1088223 | I25: 45912 | L25: 46022 | M25: 3069233 | N25: 46028 | O25: OK
A26: 08 AT DEVIS ORANGE/RIP | B26: IMI-VA-40114/017V-1 | C26: GOURBERA | D26: 2330 route de Herm | E26: 45658 | G26: =E26+14 -> 45672
A27: 08 AT DEVIS ORANGE/RIP | B27: IMI-VA-40114/018I-2 | C27: GOURBERA | D27: 3370 ROUTE DE CASTETS | E27: 45938 | F27: 45950 | G27: =E27+14 -> 45952 | I27: 45952 | L27: 45975
A28: 08 AT DEVIS ORANGE/RIP | B28: IMI-VA-40280/00HH-1 | C28: ST PERDON | D28: 1630 ROUTE DE JARDINOT | E28: 45924 | F28: 45929 | G28: =E28+14 -> 45938 | H28: 1086953 | I28: 45959 | L28: 45975
A29: 08 AT DEVIS ORANGE/RIP | B29: IMI-VE-40123/01PN-1 | C29: HERM | D29: 1403 Route de tachette | E29: 45974 | G29: =E29+14 -> 45988 | H29: 1095250 | I29: 45978 | L29: 45989
A30: 08 AT DEVIS ORANGE/RIP | B30: IMI-VA-40125/01VF-1 | C30: HEUGAS | D30: 2000 ROUTE DES BARTHES | E30: 45825 | G30: =E30+14 -> 45839 | H30: 1098250 | I30: 46006 | L30: 46042
A31: 07 AT INFO CAF REF | B31: IMI-VA-40123/01PE-1 | C31: HERM | D31: 111 CHEMIN DE LAGRANGE | E31: 45966 | G31: =E31+14 -> 45980 | I31: 45978 | L31: NA
A32: 07 AT INFO CAF REF | B32: IMI-VA-40234/007H-1 | C32: POUYDESSEAUX | D32: 78 ROUTE DE CORBLUE | E32: 45866 | G32: =E32+14 -> 45880 | P32: PB factu travaux réessayer
A33: 07 AT INFO CAF REF | B33: IMI-VA-64102/04XL-1 | C33: BAYONNE | D33: 7 rue du 49ème régiment d'infanterie | E33: 45658 | G33: =E33+14 -> 45672 | P33: PB factu travaux réessayer
A34: 07 AT INFO CAF REF | B34: IMI-VA-40283/11Q1-1 | C34: Saint vincent de paul | D34: 160 route de Gorges | E34: 45691 | G34: =E34+14 -> 45705 | H34: 1084874 | P34: Att retour Yannick
A35: 07 AT INFO CAF REF | B35: IMI-VA-40123/01KZ-1 | C35: HERM | D35: 1116 route de cluquelardit | E35: 45658 | G35: =E35+14 -> 45672 | I35: 45824 | L35: 45975 | P35: Att valid Orange trv
A36: 07 AT INFO CAF REF | B36: IMI-VA-64024/035M-3 | C36: ANGLET | D36: 3 impasse des glycines | E36: 45946 | G36: =E36+14 -> 45960 | M36: 2957114 / 3117706 | N36: 45954 | O36: OK | P36: Att valid Orange trv
A37: 07 AT INFO CAF REF | B37: IMI-VA-40114/018K-2 | C37: GOURBERA | D37: 3691 ROUTE DE CASTETS | E37: 45931 | F37: 45937 | G37: =E37+14 -> 45945 | I37: 45947 | L37: 45938 | M37: 2963583 / 3057191 | N37: 46020 | O37: OK | P37: Att valid Orange devis
A38: 07 AT INFO CAF REF | B38: IMI-VA-40088/17PG-2 | C38: DAX | D38: 76 ROUTE DE SAUBAGNACQ | E38: 46027 | G38: =E38+14 -> 46041 | I38: 46038 | L38: 46057
A39: 07 AT INFO CAF REF | B39: IMI-VA-40062/0053-1 | C39: CAMPET ET LAMOLERE | D39: 565 ROUTE DE LA TUILERIE | E39: 45875 | G39: =E39+14 -> 45889 | I39: 45901 | L39: 45902 | P39: Att valid Orange FAC
A40: 07 AT INFO CAF REF | B40: IMI-VA-64260/01SW-1 | C40: HENDAYE | D40: Rue PARCHETEGUIA | E40: 45964 | G40: =E40+14 -> 45978 | H40: 1095238 | I40: 45978 | L40: 46003 | M40: 3057219 / 3117673 | N40: 46020 | O40: OK | P40: Att valid Orange trv
...

Sheet BEIN
A1: DEPT | B1: ETAT | C1: SJ | D1: OEIE | E1: Date creation | F1: Date MAX pour CRVT 1 (9I) | G1: Date MAX pour CRVT 1 + OINE + APD (72) | H1: Date fin de travaux client | I1: CRVT3 Fin de travaux (9I et 72) | J1: Commentaire
A2: 12 | C2: 72 | D2: ROD600310 | E2: 46065 | F2: =E2+30 -> 46095 | G2: =E2+30 -> 46095

Sheet COMAC CAPFT
A1: ETAT | B1: POI | C1: COMAC/CAPFT | D1: NOMBRE D'APPUIS | E1: DATE CREATION | F1: DATE R ETUDE | G1: VILLE | H1: ADRESSE | I1: COMMENTAIRES
B2: MDM300296 | C2: COMAC | D2: 1
B3: MDM400362 | C3: COMAC | D3: 3
B4: MDM400881 | C4: COMAC | D4: 2
A5: 05 Dossier terminer | B5: NIM500036 | C5: COMAC | D5: 2
A6: 05 Dossier terminer | B6: NIM500036 | C6: CAPFT | D6: 10
A7: 05 Dossier terminer | B7: ROD400677 | C7: COMAC | D7: 1
A8: 05 Dossier terminer | B8: ROD400677 | C8: CAPFT | D8: 22
B9: ROD500059 | C9: COMAC | D9: 1 | F9: 45783 | G9: Cassagnes-Bégonhes | H9: 15 RUE DE CABRIERES
B10: ROD500237 | C10: COMAC | D10: 1
B11: ROD500352 | C11: CAPFT | D11: 15
B12: ROD500354 | C12: CAPFT | D12: 27
B13: MEN500269 | C13: CAPFT | D13: 13
B14: ROD401146 | C14: COMAC | D14: 5
B15: NIM401251
B16: MEN500305 | C16: COMAC | D16: 1
B17: ALE500143 | C17: COMAC
B18: ALE500143 | C18: CAPFT | D18: 11
B19: ROD500264 | C19: CAPFT | D19: 2
B20: RRE500282 | C20: CAPFT | D20: 5
B21: BEZ400612 | C21: CAPFT
B22: LOR500901 | C22: CAPFT | D22: 5
B23: DFE-DEP-SN-56158-0235-1 | C23: COMAC | D23: 1
B24: DFE-DEP-SN-56158-0235-1 | C24: CAPFT | D24: 3
B25: DEP-AN-56101-03HN-1 | C25: CAPFT | D25: 14
B26: DEP-AN-5615800NZ-1 | C26: CAPFT | D26: 28
A27: 04 Dossier à reprendre | B27: MEN300571 | C27: COMAC | D27: 2
A28: 05 Dossier terminer | B28: MPL301383 | C28: CAPFT | D28: 7 | E28: 45958 | F28: 45967 | G28: COURNONTERRAL | H28: 10 RUE BASTIDE DE L OULIEU
A29: 05 Dossier terminer | B29: ROD501511 | C29: COMAC | D29: 1 | G29: ESTAING | H29: 10 RUE BASTIDE DE L OULIEU
A30: 05 Dossier terminer | B30: ROD501511 | C30: CAPFT | D30: 156 | F30: 45965 | G30: ESTAING | H30: LIEU DIT SOLEILLAGES
A31: 05 Dossier terminer | B31: MEN400779 | C31: COMAC | D31: 1 | G31: MONTS DE RANDON | H31: 4 LOT LES HAUTS DE CHEYROUSES
A32: 05 Dossier terminer | B32: MEN400779 | C32: CAPFT | D32: 5 | F32: 45966 | G32: MONTS DE RANDON | H32: 4 LOT LES HAUTS DE CHEYROUSES
A33: 05 Dossier terminer | B33: ROD300381 | C33: CAPFT | D33: 23 | F33: 46041 | G33: MILLAU | H33: 90 RUE DE LA CROIX VIEILLE
A34: 05 Dossier terminer | B34: NIM500910 | C34: CAPFT | D34: 10 | F34: 45973 | G34: ST GILLES
A35: 05 Dossier terminer | B35: NIM500910 | C35: COMAC | D35: 4 | G35: ST GILLES
A36: 05 Dossier terminer | B36: LOR500901 | C36: CAPFT | D36: 10 | F36: 45974
A37: 05 Dossier terminer | B37: ROD401937 | C37: CAPFT | D37: 5 | F37: 46002 | G37: VILLEFRANCHE DE ROUERGUE | H37: 8 AVENUE PAUL RAMADIER
A38: 05 Dossier terminer | B38: NIM500846 | C38: CAPFT | D38: 2 | F38: 45996 | G38: REDESSAN | H38: 83 ROUTE DE BEAUCAIRE,
A39: 05 Dossier terminer | B39: NIM500735 | C39: CAPFT | D39: 2
A40: 05 Dossier terminer | B40: ROD502100 | C40: CAPFT | D40: 34 | F40: 46042
...

Sheet DETAIL SECTEUR
A1: MDM-DAX | C1: QPR-CRO | E1: SPI BRETAGNE | G1: BAY | I1: PAU | K1: ROD | M1: MEN | P1: Étiquettes de lignes | Q1: Somme de DRE KO | S1: Étiquettes de lignes | T1: Somme de NB DE DOSSIERS
C2: ETAT | D2: 01 AT VT | G2: ETAT | H2: POI EN TRAVAUX | I2: ETAT | J2: (Tous) | K2: ETAT | L2: (Tous) | M2: ETAT | N2: (Tous) | P2: MEN | Q2: 5 | S2: MEN | T2: 194
A3: DRE | B3: (Tous) | C3: SJ | D3: (Tous) | G3: SJ | H3: (Tous) | I3: SJ | J3: (Tous) | K3: SJ | L3: (Tous) | M3: SJ | N3: (Tous) | P3: QPR-CRO | Q3: 36 | S3: QPR-CRO | T3: 176
A4: SJ | B4: (Tous) | C4: DRE | D4: (Tous) | E4: ETAT | F4: (Tous) | G4: DRE | H4: (Tous) | I4: DRE | J4: (Tous) | K4: DRE | L4: (Tous) | M4: DRE | N4: (Tous) | P4: ROD | Q4: 7 | S4: ROD | T4: 255
A5: MOIS | B5: (Tous) | C5: MOIS | D5: (Tous) | E5: ANNEE | F5: (Tous) | G5: MOIS | H5: (Tous) | I5: mois | J5: (Tous) | K5: MOIS | L5: (Tous) | M5: MOIS | N5: (Tous) | P5: SPI BRETAGNE | S5: SPI BRETAGNE | T5: 188
A6: ANNEE | B6: (Tous) | C6: ANNEE | D6: (Tous) | E6: MOIS | F6: (Tous) | G6: ANNEE | H6: (Tous) | I6: annee | J6: (Tous) | K6: ANNEE | L6: (Tous) | M6: ANNEE | N6: (Tous) | P6: (vide) | S6: (vide)
A7: Total général | B7: =GETPIVOTDATA("POI",$B$8) -> 124 | C7: Total général | D7: =GETPIVOTDATA("POI",$C$8) -> 67 | E7: Total général | F7: =GETPIVOTDATA("COG",$E$8) -> 138 | G7: Total général | H7: =GETPIVOTDATA("POI",$G$8) -> 11 | I7: Total général | J7: =GETPIVOTDATA("POI",$I$8) -> 29 | K7: Total général | L7: =GETPIVOTDATA("POI",$K$8) -> 255 | M7: Total général | N7: =GETPIVOTDATA("POI",$M$8) -> 194 | P7: GDP AQ | Q7: 15 | S7: GDP AQ | T7: 117
A8: Étiquettes de lignes | B8: Nombre de POI | C8: Étiquettes de lignes | D8: Nombre de POI | E8: Étiquettes de lignes | F8: Nombre de COG | G8: Étiquettes de lignes | H8: Nombre de POI | I8: Étiquettes de lignes | J8: Nombre de POI | K8: Étiquettes de lignes | L8: Nombre de POI | M8: Étiquettes de lignes | N8: Nombre de POI | P8: SPI AQ | S8: SPI AQ | T8: 84
A9: AMOU | B9: 1 | C9: AUDIERNE | D9: 1 | E9: CAUDAN | F9: 1 | G9: ANGLET | H9: 3 | I9: ARAMITS | J9: 5 | K9: AURIAC-LAGAST | L9: 1 | M9: ARZENC DE RANDON | N9: 1 | P9: Total général | Q9: 63 | S9: Total général | T9: 1014
A10: ARGELOS | B10: 1 | C10: BENODET | D10: 2 | E10: CLEGUER | F10: 1 | G10: BAYONNE | H10: 2 | I10: ARTIGUELOUVE | J10: 1 | K10: BALAGUIER SUR RANCE | M10: GRABELS | N10: 1
A11: AUREILHAN | B11: 1 | C11: COMBRIT | D11: 2 | E11: ERGUE GABERIC | F11: 3 | G11: BIARRITZ | H11: 2 | I11: BUROS | J11: 1 | K11: LA BORIE DE POUJADE | L11: 1 | M11: NIMES | N11: 1
A12: BAHUS SOUBIRAN | B12: 1 | C12: PLOMEUR | D12: 3 | E12: HENNEBONT | F12: 1 | G12: BIDART | H12: 1 | I12: COARRAZE | J12: 1 | K12: BROMMAT | L12: 1 | M12: ALBARET LE COMTAL | N12: 1
A13: BEGAAR | B13: 1 | C13: PLONEOUR LANVERN | D13: 1 | E13: LANESTER | F13: 3 | G13: BOUCAU | H13: 1 | I13: DOAZON | J13: 1 | K13: ESPALION | L13: 1 | M13: ALBARET SAINTE MARIE | N13: 1
A14: BENESSE MAREMNE | B14: 1 | C14: PLOUHINEC | D14: 1 | E14: LOCMIQUELIC | F14: 1 | G14: LABENNE | H14: 1 | I14: GAN | J14: 2 | K14: LESTRADE ET THOUELS | M14: ALBARET STE MARIE | N14: 2
A15: BENQUET | B15: 3 | C15: PONT L ABBE | D15: 1 | E15: LORIENT | F15: 6 | G15: LAHONCE | H15: 1 | I15: GELOS | J15: 1 | K15: LD TAYSSES | L15: 1 | M15: ALES | N15: 1
A16: 570 AV MARSAN | B16: 1 | C16: RIEC SUR BELON | D16: 1 | E16: PLESCOP | F16: 1 | G16: Total général | H16: 11 | I16: GERDEREST | J16: 1 | K16: MILLAU | L16: 2 | M16: ALLENC | N16: 2
A17: 1076 RTE DE HAUT MAUCO | B17: 1 | C17: PLOEMEUR | D17: 1 | E17: PLOEMEUR | F17: 4 | I17: HAGETAUBIN | J17: 1 | K17: SAINT CHELY D AUBRAC | L17: 1 | M17: ARZENC DE RANDON | N17: 2
A18: 62 AVENUE DU MARSAN | B18: 1 | C18: LE CROISTY | D18: 1 | E18: PORT LOUIS | F18: 1 | I18: JURANCON | J18: 2 | K18: VERRIERES | M18: AUROUX | N18: 1
A19: BISCARROSSE | B19: 1 | C19: MESLAN | D19: 1 | E19: QUEVEN | F19: 1 | I19: LABATUT | J19: 1 | K19: 1 CONCLUS | L19: 1 | M19: BADAROUX | N19: 2
A20: BOUGUE | B20: 1 | C20: SAINT CARADEC TREGOMEL | D20: 1 | E20: QUIMPER | F20: 13 | I20: LALONGUE | J20: 1 | K20: VILLEFRANCHE DE PANAT | M20: BALSIEGES | N20: 3
A21: CAMPAGNE | B21: 2 | C21: QUIMPER | D21: 1 | E21: RENNES | F21: 90 | I21: LESCAR | J21: 1 | K21: 6 AV DE LA PLAGE | L21: 1 | M21: BANASSAC-CANILHAC | N21: 8
A22: CAMPET ET LAMOLERE | B22: 1 | C22: QUIBERON | D22: 5 | E22: ALLEE DE LA GARAYE | F22: 1 | I22: LOUVIE JUZON | J22: 1 | K22: AGUESSAC | L22: 6 | M22: BARJAC | N22: 3
A23: CASTELNER | B23: 1 | C23: THEIX NOYALO | D23: 1 | E23: ALLEE JEAN DE LA VARENDE | F23: 1 | I23: MEILLON | J23: 1 | K23: ALRANCE | L23: 3 | M23: BEL-AIR-VAL-D'ANCE | N23: 1
A24: CERE | B24: 1 | C24: BERRIC | D24: 1 | E24: AVENUE ANDRE MALRAUX | F24: 1 | I24: MIOSSENS | J24: 1 | K24: ARGENCE EN AUBRAC | L24: 1 | M24: BEZIERS | N24: 2
A25: DAX | B25: 2 | C25: MONTAUBAN DE BRETAGNE | D25: 3 | E25: AVENUE AUGUSTE BRIZEUX | F25: 1 | I25: MIREPEIX | J25: 2 | K25: ARVIEU | L25: 2 | M25: BORNE | N25: 1
A26: GAILLERES | B26: 1 | C26: PIRE CHANCE | D26: 2 | E26: AVENUE DES PAYS BAS | F26: 1 | I26: MORLANNE | J26: 1 | K26: AUBIN | M26: BOURGS SUR COLAGNE | N26: 6
A27: GAMARDE LES BAINS | B27: 1 | C27: GOURIN | D27: 1 | E27: AVENUE GROS MALHON | F27: 1 | I27: OGEU LES BAINS | J27: 1 | K27: 5 PL JEAN JAURES à AUBIN | L27: 1 | M27: BRENOUX | N27: 1
A28: GEAUNE | B28: 3 | C28: GOUESNACH | D28: 1 | E28: AVENUE JEAN JANVIER | F28: 2 | I28: ORTHEZ | J28: 1 | K28: AURIAC-LAGAST | L28: 1 | M28: CANS ET CEVENNES | N28: 2
A29: GOOS | B29: 1 | C29: HENT REUNIOU | D29: 1 | E29: AVENUE JORGE SEMPRUN | F29: 1 | I29: PAU | J29: 1 | K29: AUZITS | L29: 1 | M29: CASTELNAU LE LEZ | N29: 1
A30: GOURBERA | B30: 5 | C30: THORIGNE FOUILLARD | D30: 1 | E30: BOULEVARD ALBERT 1ER | F30: 1 | I30: SAINT CASTIN | J30: 1 | K30: BASSE CURVALLE | L30: 1 | M30: CAUSSES | N30: 1
A31: HABAS | B31: 1 | C31: 25 RUE NATIONALE 12 | D31: 1 | E31: BOULEVARD ALEXIS CARREL | F31: 1 | I31: (vide) | K31: BELMONT SUR RANCE | L31: 5 | M31: CHADENET | N31: 1
A32: HERM | B32: 22 | C32: RENNES | D32: 1 | E32: BOULEVARD DE BULGARIE | F32: 1 | I32: Total général | J32: 29 | K32: BERTHOLENE | L32: 3 | M32: CHANAC | N32: 2
A33: HORSARRIEU | B33: 1 | C33: BD LA TOUR D AUVERGNE | D33: 1 | E33: BOULEVARD DE CHEZY | F33: 1 | K33: BOZOULS | L33: 4 | M33: CHASTEL NOUVEL | N33: 1
A34: LAGLORIEUSE | B34: 2 | C34: REDON | D34: 1 | E34: BOULEVARD DE LA GUERINAIS | F34: 1 | K34: BRANDONNET | L34: 1 | M34: CHAULHAC | N34: 1
A35: LESGOR | B35: 1 | C35: RUE DU PARADET | D35: 1 | E35: BOULEVARD DE LA TOUR D AUVERGNE | F35: 1 | K35: BROMMAT | L35: 2 | M35: COUCOURON | N35: 1
A36: LESPERON | B36: 1 | C36: TREGUNC | D36: 1 | E36: BOULEVARD DE SEVIGNE | F36: 2 | K36: BROMMET | L36: 1 | M36: ESCLANEDES | N36: 1
A37: MAYLIS | B37: 1 | C37: 37B RTE MELGVEN | D37: 1 | E37: BOULEVARD JEANNE D ARC | F37: 1 | K37: BROUSSE LE CHATEAU | L37: 2 | M37: FLORAC | N37: 2
A38: MAZEROLLES | B38: 1 | C38: VITRE | D38: 1 | E38: BOULEVARD SAINT JEAN BAPTISTE DE LA SAL | F38: 1 | K38: CALMONT | M38: GENERAC | N38: 1
A39: MEES | B39: 2 | C39: R DU COLLEGE | D39: 1 | E39: LE PLESSIX LOUVEL | F39: 1 | K39: 689 ROUTE DE CATUSSE | L39: 1 | M39: GORGES DU TARN CAUSSES | N39: 1
A40: MEZOS | B40: 3 | C40: SAINT JEAN BREVELAY | D40: 1 | E40: MAIL FELIX LECLERC | F40: 1 | K40: LE PUECH SAINT AMANS | L40: 1 | M40: GRABELS | N40: 2
...

Sheet Feuil2
A1: 01 AT VT | D1: 01 VT A FAIRE | F1: 01 Dossier à monter
A2: 01.2 A REMONTER | D2: 01.2 A REMONTER | F2: 02 En cours
A3: 02 RETOUR VT | D3: 02 RETOUR VT | F3: 03 Att Infos
A4: 03 DOSSIER A REPRENDRE | D4: 03 DOSSIER A REPRENDRE | F4: 04 Dossier à reprendre
A5: 04 DOSSIER A MONTER | D5: 04 DOSSIER A MONTER | F5: 05 Dossier terminer
A6: 05 AT INFO CAF REF | D6: 05 AT PV
A7: 05.1 ETU TRANSMISE | D7: 05.1 AT DTA
A8: 06 AT DEVIS CLIENT | D8: 05.2 ATT DT
A9: 07 AT TRVX CLIENT | D9: 06 AT MAJ SI
A10: 08 AT COMAC/CAPFT | D10: 07 AT INFO CAF REF
A11: 09 AT DEVIS ORANGE/RIP | D11: 08 AT DEVIS ORANGE/RIP
A12: 10 AT PV | D12: 09 POI EN TRAVAUX
A13: 10.1 ATT DT | D13: 09.1 ATT DOE
A14: 11 AT DTA | D14: 10 POI EN FACTU
A15: 12 AT MAJ SI | D15: 11 RECOL A FAIRE
A16: 13 ETAT 5
A17: 14 POI EN TRAVAUX
A18: 14.1 AT RETOUR DOE
A19: 15 POI FACTU
A20: 16 DOSSIER PAYE

Sheet TP SWAN
A1: Act | B1: Département | C1: Ilot | D1: Centre | E1: Acteur | F1: Référence | G1: Commune | H1: besoin TP | I1: Date TP | J1: Etat/Plannif | K1: N° SWAN
A2: QRL | B2: 12 | C2: PV5 | D2: REQ | E2: FRAL TELECOM | F2: 12.TR210021-REQUISTA | G2: REQUISTA | H2: OUI | I2: 45910 | J2: Préparé | K2: T508176152
A3: QRL | B3: 12 | C3: PV5 | D3: LAG | E3: FRAL TELECOM | F3: CEOCE2502G80727=1 | H3: OUI | I3: 45911 | J3: Préparé | K3: T508195785
A4: QRL | B4: 12 | C4: PV5 | D4: RIG | E4: FRAL TELECOM | F4: CEOCE2502L30879=1 | G4: TR210007 | H4: OUI | I4: 45912 | J4: Préparé | K4: T508198605
A5: QRL | B5: 12 | C5: PV5 | D5: FOD | E5: FRAL TELECOM | F5: 12.TR190005-CORNUS | G5: FONDAMENTE | H5: OUI | I5: 45917 | J5: Préparé | K5: T508196045
A6: QRL | B6: 12 | C6: PV5 | D6: BE7 | E6: FRAL TELECOM | F6: 12.TR190096-BELMONT | G6: BELMONT SUR RANCE | H6: OUI | I6: 45918 | J6: Préparé | K6: T508216813
A7: QRL | B7: 12 | C7: PV5 | D7: STA | E7: FRAL TELECOM | F7: 12.TR200015-STAMANS | G7: ST AMANS DES COTS | H7: OUI | I7: 45919 | J7: Préparé | K7: T508227833
A8: QRL | B8: 12 | C8: PV5 | D8: CAV | E8: FRAL TELECOM | F8: CEOCE2502G93108=1 | H8: OUI | I8: 45924 | J8: Préparé | K8: T508228091
A9: QRL | B9: 12 | C9: PV5 | D9: BAR | E9: FRAL TELECOM | F9: CEOCE2503O13791=1 | H9: OUI | I9: 45925 | J9: Préparé | K9: T508228156
A10: QRL | B10: 12 | C10: PV5 | D10: MHH | E10: FRAL TELECOM | F10: R503642203A | H10: OUI | I10: 45926 | J10: Préparé | K10: T508228203
A11: QRL | B11: 12 | C11: PV5 | D11: FOD | E11: FRAL TELECOM | F11: 12.TR180006-LECLAPIER | G11: FONDAMENTE | H11: OUI | I11: 45931 | J11: Préparé | K11: T509084396
A12: QRL | B12: 48 | C12: PV5 | D12: GTE | E12: FRAL TELECOM | F12: ACC0050YEG1 | H12: OUI | I12: 45932 | J12: Préparé | K12: T508179899
A13: QRL | B13: 12 | C13: PV5 | D13: CBO | E13: FRAL TELECOM | F13: CEOCE2506T79802=1 | H13: OUI | I13: 45932 | J13: Préparé | K13: T509142602
A14: QRL | B14: 12 | C14: PV5 | D14: SCY | E14: FRAL TELECOM | F14: CEOCE2506V25832=1 | H14: OUI | I14: 45933 | J14: Préparé | K14: T509085631
A15: QRL | B15: 12 | F15: R507687771A | H15: OUI | I15: 45936 | J15: Préparé | K15: T509141071
A16: QRL | B16: 12 | C16: PV5 | E16: FRAL TELECOM | F16: R503644785A | I16: 45937 | J16: Préparé | K16: T509097195
A17: DPS | B17: 12 | C17: PV5 | D17: VEL | E17: FRAL TELECOM | F17: CEOCE2507H53654=1 | H17: OUI | I17: 45938 | J17: Préparé | K17: T509156405
A18: QRL | B18: 12 | C18: PV5 | D18: CN4 | E18: FRAL TELECOM | F18: R502635967A | G18: CORNUS | H18: OUI | I18: 45939 | J18: Préparé | K18: T509086008
B19: 12 | C19: PV5 | D19: CPI | E19: FRAL TELECOM | F19: CEOCE2507I41327=1 | H19: OUI | I19: 45940 | J19: Préparé | K19: T509156474
F20: R507688532A | H20: OUI | I20: 45943 | J20: Préparé | K20: T509143215
B21: 12 | C21: PV5 | D21: ENT | E21: FRAL TELECOM | F21: CEOCE2507F75413=1 | H21: OUI | I21: 45944 | J21: Préparé | K21: T509156539
A22: QRL | B22: 12 | C22: PV5 | D22: MPX | E22: FRAL TELECOM | F22: R503646300A | G22: Peux-et-Couffouleux 12360 | H22: OUI | I22: 45945 | J22: REJETE | K22: T509086131 | L22: ATT RETOUR
A23: QRL | B23: 12 | C23: PV5 | D23: AGU | E23: FRAL TELECOM | F23: 12.TR210048-RIVIERES | G23: AGUESSAC | H23: OUI | I23: 45946 | J23: Préparé | K23: T509090350
A24: QRL | B24: 12 | C24: PV5 | D24: LST | E24: FRAL TELECOM | F24: 12.TR190072-LASSOUTS | G24: LASSOUTS | H24: OUI | I24: 45947 | J24: Préparé | K24: T509090497
C25: PV5 | D25: MBZ | E25: FRAL TELECOM | F25: CEOCE2507K89152=1 | G25: MONTBAZENS | H25: OUI | I25: 45950 | J25: Préparé | K25: T509195999
A26: QRL | B26: 12 | C26: PV5 | D26: RTM | E26: FRAL TELECOM | F26: VIA01000000205321667 | H26: OUI | I26: 45950 | J26: Préparé | K26: T509226805 | L26: PRO$194335$2398$OK2800m CABLE L1092 24FO MODULO 6 FTTHtype de modification: POSE 1 PEO AVEC CHANGEMENT DE CABLEIdentifiant tronçon: Tr 200041Du PB Pt 000432 x 24 soudures au PEO Poteau n159182 x 24souduresCommentaires : Remplacer 800m de 24 fo m6 du pt 000432 aupoteau 159204 au poteau 159182 le remplacement englobe 2casseCommande : ROD501214
A27: QRL | B27: 12 | C27: PV5 | D27: ABB | E27: FRAL TELECOM | F27: R508700248A | H27: OUI | I27: 45951 | J27: Préparé | K27: T509226915 | L27: PRO$194110$1640$OK2 500m CABLE L1092 12FO MODULO 6 FTTHtype de modification: POSE 2 PEOIdentifiant tronçon: Tr 200221Du PEO Poteau n2125412 x 12 soudures au PEO Poteaun2125424 x 12 soudures
A28: QRL | B28: 12 | C28: PV5 | D28: SCU | E28: FRAL TELECOM | F28: CEOCE2508O85725=1 | G28: SALLE CURAN | H28: OUI | I28: 45951 | J28: Préparé | K28: T509226970 | L28: PRO$194485$2838$OK2 400m CABLE L1092 72FO MOD 12 FTTHtype de modification: POSE 2 PEOIdentifiant tronçon: Tr 18 0028Du PEO 21750 x 72 soudures au PEO 21736 x 72 soudures
A29: QRL | B29: 12 | C29: PV5 | D29: LRO | E29: FRAL TELECOM | F29: R506678556A | H29: OUI | I29: 45952 | J29: Préparé | K29: T509105640
A30: QRL | B30: 12 | C30: PV5 | D30: RUL | E30: FRAL TELECOM | F30: VIA01000000215839749 | H30: OUI | I30: 45952 | J30: Préparé | K30: T509227058 | L30: PRO$178237$1190$OK2 ý190m CABLE L1092 24FO MODULO 6 FTTHýtype de modification: POSE 2 PEOýIdentifiant tronçon: Tr 210144ýDu PEO Chambre 99987 x 24 soudures au PEO Poteau 2127896 xý24 souduresýCOMMANDE : ROD501027
A31: QRL | B31: 12 | C31: PV5 | D31: QUI | E31: FRAL TELECOM | F31: R412603424A | H31: OUI | I31: 45953 | J31: Préparé | K31: T509141025 | L31: Câble introuvable
A32: QRL | B32: 12 | C32: PV5 | D32: DRU | E32: FRAL TELECOM | F32: CEOCE2507H78827=1 | G32: DRUELLE | H32: OUI | I32: 45953 | J32: Préparé | K32: T509227106 | L32: PRO$191026$1912$OK2 300m CABLE L1092 36FO MOD 12 FTTHtype de modification: POSE 2 PEOIdentifiant tronon: TR 19 0007Du PEO 226271 x 36 soudures au PEO 226264 x 36 souduresCommentaires : 300m de 36FO L1092 M12 doit tre remplaceavec cration de 2 PEP, 1 sur le poteau 226271 et 1 sur lepoteau 226264. 2 poteau cass: 226269 et 226270 remplacs le 26/07/25 via GESTAR250717DRU4986251.Commande : ROD501217 | O32: PRO$191026$1912$OK2 300m CABLE L1092 36FO MOD 12 FTTHtype de modification: POSE 2 PEOIdentifiant tronon: TR 19 0007Du PEO 226271 x 36 soudures au PEO 226264 x 36 souduresCommentaires : 300m de 36FO L1092 M12 doit tre remplaceavec cration de 2 PEP, 1 sur le poteau 226271 et 1 sur lepoteau 226264. 2 poteau cass: 226269 et 226270 remplacs le 26/07/25 via GESTAR250717DRU4986251.Commande : ROD501217
A33: QRL | B33: 12 | C33: PV5 | D33: RIG | E33: FRAL TELECOM | F33: VIA01000000189767359 | H33: OUI | I33: 45954 | J33: Préparé | K33: T509114327
A34: QRL | B34: 12 | C34: PV5 | D34: SVI | E34: FRAL TELECOM | F34: CEOCE2508O31257 | H34: OUI | I34: 45954 | J34: Préparé | K34: T509227327 | L34: CEOCE2508O31257** TR200008 350M 72FO L1092 M12Du PEO 9867 x 72 soudures au PEO 9856 x 72 souduresPRO$194557$2682$OK2
A35: QRL | B35: 12 | C35: PV5 | D35: FIR | E35: FRAL TELECOM | F35: R503640957A | H35: OUI | I35: 45957 | J35: Préparé | K35: T509227496 | L35: NVORA*R503640957A* 200M 12FO L1092 M6 ýDu poteau 126740( création de boite ) au poteau 1033211(ýrécupération du pt 000603)ýplus remplacer poteau 2123499 VIA GESTAR250710FIR4978771ýCABLE DISPO A SALLES-LA-SOURCE EN SORTIE COMPTOIR. TR 20 0314
A36: QRL | B36: 12 | C36: PV5 | D36: SCH | E36: FRAL TELECOM | F36: CEOCE2507L39259=1 | H36: OUI | I36: 45957 | J36: Préparé | K36: T509227582 | L36: NVSOG**CEOCE2507L39259=1** TR190018 250M 36FO L1092 M12250m 36fom12 doit être remplacée avec creation de deux pep,1 sur le ptx 94556, 1 sur le ptx 94560.REO PRO validée avec modification d ingénierie. 250M de 36foDossier sur BO5PRO$192718$1795$OK2
A37: QRL | B37: 12 | C37: PV5 | D37: SLE | E37: FRAL TELECOM | F37: CEOCE2501T10797=1 | H37: OUI | I37: 45958 | J37: Préparé | K37: T509227628 | L37: NVORA**CEOCE2501T10797=1** 380m de L1092 24FO M6 du poteauý112466 a la chambre l2c code 00941/12270 + création 2 boitesý- 1 au poteau 112466 et l'autre dans la chambre l2c code n°ý00941/12270ýCommande de régul : ROD500828
A38: QRL | B38: 12 | C38: PV5 | D38: FOD | E38: FRAL TELECOM | F38: CEOCE2508O35486=1 | G38: FONDAMENTE | H38: OUI | I38: 45958 | J38: Préparé | K38: T509227664 | L38: NVFT**CEOCE2508O35486=1** TR180006 700M 36FO L1092 M6Du PEO Pt 000017 x 36 soudures au PEO Poteau 196194 x 36soudures700 m dz 36fo m12 a remplacer du pt 000017 au poteau 196194Sur le terrain nous n avons pas trouver le pt 000017 alorsil faudra crée la boîte pt 000017 au poteau 196207PRO$194746$2690$OK2
A39: QRL | B39: 12 | C39: PV5 | D39: EST | E39: FRAL TELECOM | F39: CEOCE2507F32934=1 | H39: OUI | I39: 45959 | J39: Préparé | K39: T509227739 | L39: PRO$189709$2882$OK2 500m CABLE L1092 72FO MOD 12 FTTHtype de modification: POSE 1 PEO AVEC CHANGEMENT DE CABLEIdentifiant tronçon: Tr200010Du PEP Pt 000008 x 72 soudures au PEO Ptx 3120203 x 72soudures
A40: QRL | B40: 48 | C40: PV5 | D40: SAM | E40: FRAL TELECOM | F40: CEOCE2503S05538=1 | H40: OUI | I40: 45960 | J40: Préparé | K40: T509114398
...

Sheet SPI Bretagne
B1: =COUNTA(B3:B844) -> 158
A2: ETAT | B2: COG | C2: INSEE | D2: Ville | E2: ADRESSE | F2: Commentaire
A3: Dossier Envoyé | B3: IMI-VS-35238/JGJH-1 | C3: 35238 | D3: RENNES | E3: AVENUE JEAN JANVIER | G3: Dossier Payé
A4: Dossier Envoyé | B4: IMI-VS-35238/JQPB-1 | C4: 35238 | D4: RENNES | E4: PLACE DE SERBIE | G4: Dossier Envoyé
A5: Dossier Envoyé | B5: IMI-VS-35238/JS1G-1 | C5: 35238 | D5: RENNES | E5: ALLEE DE LA GARAYE | G5: Dossier Bloqué
A6: Dossier Envoyé | B6: IMI-VS-35238/JSDA-1 | C6: 35238 | D6: RENNES | E6: SQUARE YVES MONTAND | G6: Dossier Affecté
A7: Dossier Envoyé | B7: IMI-VS-35238/JUKE-1 | C7: 35238 | D7: RENNES | E7: SQUARE DU ROI ARTHUR | G7: Dosseir en Retour
A8: Dossier Envoyé | B8: IMI-VS-35238/JW4I-1 | C8: 35238 | D8: RENNES | E8: PLACE MARECHAL JUIN | G8: Etude Terminé
A9: Dossier Envoyé | B9: IMI-VS-35238/JMYV-1 | C9: 35238 | D9: RENNES | E9: RUE LOUIS POSTEL
A10: Dossier Envoyé | B10: IMI-VS-35238/JU6I-1 | C10: 35238 | D10: RENNES | E10: AVENUE GROS MALHON
A11: Dossier Envoyé | B11: IMI-VS-35238/JEWQ-1 | C11: 35238 | D11: RENNES | E11: QUAI DE LA PREVALAYE
A12: Dossier Envoyé | B12: IMI-VS-35238/JF3Y-1 | C12: 35238 | D12: RENNES | E12: RUE DES TRENTE
A13: Dossier Envoyé | B13: IMI-VS-35238/JFE4-1 | C13: 35238 | D13: RENNES | E13: RUE LEGRAVEREND
A14: Dossier Envoyé | B14: IMI-VS-35238/JMR9-1 | C14: 35238 | D14: RENNES | E14: RUE DE LA CRECHE
A15: Dossier Envoyé | B15: IMI-VS-35238/JUEJ-1 | C15: 35238 | D15: RENNES | E15: RUE DE LEON
A16: Dossier Envoyé | B16: IMI-VS-35238/JUUS-1 | C16: 35238 | D16: RENNES | E16: PLACE DU MONTENEGRO
A17: Dossier Envoyé | B17: IMI-VS-35238/JW0C-2 | C17: 35238 | D17: RENNES | E17: RUE FRANCOIS LANNO
A18: Dossier Envoyé | B18: IMI-VS-35238/JX0J-1 | C18: 35238 | D18: RENNES | E18: BOULEVARD JEANNE D ARC
A19: Dossier Envoyé | B19: IMI-VS-35238/JX98-1 | C19: 35238 | D19: RENNES | E19: MAIL FRANCOIS MITTERRAND
A20: Dossier Envoyé | B20: IMI-VS-35238/JWUD-1 | C20: 35238 | D20: RENNES | E20: RUE EDOUARD JORDAN
... A22: Dossier Envoyé | B22: IMI-VS-35238/JGWC-1 | C22: 35238 | D22: RENNES | E22: RUE JOSEPH SAUVEUR
A23: Dossier Bloqué | C23: 35238 | D23: RENNES | E23: AVENUE JORGE SEMPRUN | F23: Dossier retiré par Sogtrel
A24: Dossier Envoyé | B24: IMI-VS-35238/JQUC-3 | C24: 35238 | D24: RENNES | E24: BOULEVARD DE BULGARIE
A25: Dossier Envoyé | B25: IMI-VS-35238/JR18-1 | C25: 35238 | D25: RENNES | E25: RUE SAINT MALO
A26: Dossier Envoyé | B26: IMI-VS-35238/JTVL-1 | C26: 35238 | D26: RENNES | E26: RUE DE BREST
A27: Dossier Envoyé | B27: IMI-VS-35238/JU9S-1 | C27: 35238 | D27: RENNES | E27: RUE ARTHUR FONTAINE
A28: Dossier Envoyé | B28: IMI-VS-35238/JVAW-1 | C28: 35238 | D28: RENNES | E28: RUE DE LA SANTE
A29: Dossier Envoyé | B29: IMI-VS-35238/01SP-1 | C29: 35238 | D29: RENNES | E29: RUE DE NORMANDIE
A30: Dossier Envoyé | B30: IMI-VS-35238/JGPR-1 | C30: 35238 | D30: RENNES | E30: BOULEVARD DE SEVIGNE
A31: Dossier Envoyé | B31: IMI-VS-35238/00P2-1 | C31: 35238 | D31: RENNES | E31: ALLEE JEAN DE LA VARENDE
A32: Dossier Envoyé | B32: IMI-VS-35238/JKVR-1 | C32: 35238 | D32: RENNES | E32: RUE ETIENNE PINAULT
A33: Dossier Envoyé | B33: IMI-VS-35238/JTFQ-1 | C33: 35238 | D33: RENNES | E33: RUE DE BREST
A34: Dossier Envoyé | B34: IMI-VS-35238/00YY-1 | C34: 35238 | D34: RENNES | E34: RUE D ANTRAIN
A35: Dossier Envoyé | B35: IMI-VS-35238/JIP8-1 | C35: 35238 | D35: RENNES | E35: RUE LE GUEN DE KERANGAL
... A123: Dossier Envoyé | B123: IMI-VS-29232/0995-2 | C123: 29232 | D123: QUIMPER | E123: RUE ETIENNE GOURMELEN
A124: Dossier Envoyé | B124: IMI-VE-35238/JF7A-1 | C124: 35238 | D124: RENNES | E124: 13, R . Monnaie, 35000, RENNES
A125: Dossier Envoyé | B125: DEP-AN-29232/028Q-1
A126: Dossier Envoyé | B126: DEP-AN-35144/00JE-1 | C126: 35144 | D126: Langan | E126: 14 Impasse Bernard Moitessier 35850 Langan
A127: Dossier Bloqué | B127: DEP-AN-29232/0JB3-1 | E127: 4 Rue du Palais 29000 Quimper | F127: MAIL POUR RDV
A128: Etude Terminé | B128: DEP-AN-29232/03U7-1 | E128: 9 Rue de l'Île d'Houât - Quimper
...

Sheet DEMANDE DT
A1: INFORMATIONS GENERAL | F1: CONCESSIONAIRE
A2: POI | B2: COMMUNE | C2: ADRESSE | D2: COORDONEE GPS | E2: N°REF DT | F2: ENEDIS | G2: GRDF | H2: EAU | I2: MAIRIE | J2: SYNDICAT ENERGIE | K2: DEPARTEMENT | L2: INFRA
A3: MEN400681 | B3: Saint-Laurent-de-Veyrès | C3: Village | D3: 44.77531717412041, 3.133627254156568 | E3: 2024121100559TEU | F3: OK | G3: N/C | H3: N/C | I3: N/C | J3: N/C | K3: N/C | L3: N/C
A4: MEN400685 | B4: CHATEAUNEUF DE RANDON | C4: 3 ROUTE DU PONT RODIER | D4: 44.63415889866625, 3.6752155378601734 | E4: 2024121000466T0D | F4: OK | G4: N/C | K4: OK
A5: ROD401860 | B5: SAINT SERNIN SUR RANCE | C5: 22 CHEMIN DE LAVAL | D5: 43.88032959324717, 2.60623579330839 | E5: 2024120500225TFZ | F5: OK | G5: N/C | H5: OK | I5: N/C | J5: N/C | K5: N/C | L5: N/C
A6: ROD401858 | B6: LA LOUBIERE | C6: IMP DU COMBAL | D6: 44.40716 ; 2.63976 | E6: 2024121600193TDF | F6: OK | G6: OK | H6: OK | I6: OK | J6: OK | K6: N/C | L6: OK (altitude)
A7: ROD402081 | B7: SAINT SERNIN SUR RANCE | C7: 22 CHEMIN DE LAVAL | D7: 43.880314057028876, 2.6062056722738514 | E7: 2024121600166TIA | F7: OK | G7: N/C | H7: OK | I7: N/C | J7: N/C | K7: N/C | L7: N/C
A8: ROD402078 | B8: ROQUEFORT SUR SOULZON | C8: L AIRE VIEILLE | D8: 43.97273 ; 2.95984 | E8: 2024121600531TPV | F8: OK | G8: OK | H8: N/C | I8: OK | J8: N/C | K8: N/C | L8: N/C
A9: MEN400754 | B9: LA MALENE | C9: ROUTE DE CAUQUENAS | D9: 44.32049 ; 3.30010 | E9: 2024121600807TIY | F9: OK | G9: N/C | H9: N/C | I9: N/C | J9: N/C | K9: N/C | L9: N/C
A10: ROD402113 | B10: ALRANCE | C10: 2 CITE EDF | D10: 44.12151 ; 2.68751 | E10: 2024121700826TQX | F10: OK | G10: N/C | H10: OK | I10: N/C | J10: N/C | K10: N/C | L10: OK
A11: ROD400178 | B11: GABRIAC | C11: LD LE JALOUS | D11: 44.45969820887255, 2.8107440949066063 | E11: 2024121801016TIA | F11: OK | G11: N/C | H11: OK | I11: N/C | J11: N/C | K11: N/C | L11: N/C
